Workbook

Sheet README
A1: NexaLearn x Yuno — Financial Impact Model (supporting workbook)
A2: Illustrative model. All figures annual, USD. Baseline = NexaLearn finance actuals ($89M TPV) [D].
A4: Origin tags (same as the proposal document):
A5: [D] Dossier data [C] Our calculation [P] Public source (see Sources) [H] Hypothesis to validate with NexaLearn
A7: Colour code:
A8: Blue text = input you can change · Black = formula · Green = link to Inputs sheet · Yellow fill = key assumption
A10: Sheets:
A11: Inputs — every assumption, with tag and source
A12: Model — PSP fees by segment, TCO in 3 scenarios, revenue recovery, net benefit and payback
A13: Sensitivity — transaction-count and volume sensitivities
A15: Sources:
A16: [P1] Stripe pricing (US): 2.9% + $0.30; +1.5% international cards; +1% currency conversion — https://stripe.com/pricing
... A20: [P5] Xendit Indonesia: QRIS 0.7%; OVO/GoPay for digital merchants 5.0–5.5% — https://www.xendit.co/en-id/pricing/

Sheet Inputs
A1: Inputs & assumptions
A3: A. Payment segments and pricing by scenario
A4: Segment | B4: Annual volume ($) | C4: Transactions | D4: Current PSP | E4: Current % | F4: Current $/tx | G4: Stripe offer % | H4: Stripe offer $/tx | I4: Yuno route — cons % | J4: Yuno route — cons $/tx | K4: Yuno route — base % | L4: Yuno route — base $/tx | M4: Tag / rationale
A5: SEA — Stripe cards | B5: 23300000 | C5: 810000 | D5: Stripe | E5: 0.029 | F5: 0.3 | G5: 0.026 | H5: 0.25 | I5: 0.026 | J5: 0.25 | K5: 0.026 | L5: 0.25 | M5: [D][C] SEA $34M minus Xendit $10.7M; tx = 920K minus Xendit 110K. Stays on Stripe (discounted) under Yuno
A6: SEA — Xendit APMs | B6: 10700000 | C6: 110000 | D6: Xendit | E6: 0.032 | F6: 0.25 | G6: 0.032 | H6: 0.25 | I6: 0.032 | J6: 0.25 | K6: 0.032 | L6: 0.25 | M6: [D] Tx derived from $27.5K fixed fees / $0.25 [C]. Unchanged: local wallets cost more, not less [P5]
A7: India | B7: 18000000 | C7: 340000 | D7: Stripe | E7: 0.029 | F7: 0.3 | G7: 0.026 | H7: 0.25 | I7: 0.025 | J7: 0 | K7: 0.02 | L7: 0 | M7: [D] volume/tx. Yuno route = local acquiring + UPI: base 2.0%, cons 2.5% [H]; ref. Razorpay 2% cards, zero-MDR UPI [P4]
A8: Africa | B8: 8900000 | C8: 190000 | D8: Paystack | E8: 0.035 | F8: 0.15 | G8: 0.035 | H8: 0.15 | I8: 0.025 | J8: 0 | K8: 0.02 | L8: 0 | M8: [D] volume/tx. Stripe offer does not change Paystack. Yuno route = local acquiring: base 2.0%, cons 2.5% [H]; ref. Paystack local NG cards 1.5% [P3]
A9: LatAm | B9: 11000000 | C9: 280000 | D9: Stripe | E9: 0.029 | F9: 0.3 | G9: 0.026 | H9: 0.25 | I9: 0.03 | J9: 0 | K9: 0.025 | L9: 0 | M9: [D] volume/tx. Yuno route = local acquiring + Pix/OXXO: base 2.5%, cons 3.0% [H]; ref. Pix 2% list [P2]
A10: Europe | B10: 10000000 | C10: 240000 | D10: Stripe | E10: 0.029 | F10: 0.3 | G10: 0.026 | H10: 0.25 | I10: 0.026 | J10: 0.25 | K10: 0.026 | L10: 0.25 | M10: [D] Stays on Stripe (already local acquiring)
A11: North America | B11: 7100000 | C11: 230000 | D11: Stripe | E11: 0.029 | F11: 0.3 | G11: 0.026 | H11: 0.25 | I11: 0.026 | J11: 0.25 | K11: 0.026 | L11: 0.25 | M11: [D] Stays on Stripe (domestic processing)
A12: Total | B12: =SUM(B5:B11) -> 89000000 | C12: =SUM(C5:C11) -> 2200000 | M12: [C] Regional table sums to 2.2M tx vs 2.1M stated by NexaLearn — see Sensitivity
A14: B. Approval-rate uplift by region (applied to attempted volume)
A15: Region | B15: Approved volume ($) | C15: Current approval rate | D15: Uplift — conservative (pts) | E15: Uplift — base (pts) | F15: Rationale
A16: Southeast Asia | B16: =B5+B6 -> 34000000 | C16: 0.81 | D16: 0.015 | E16: 0.03 | F16: [D] Cross-border cards: Indonesia 76%, Philippines 78%. Lower uplift because Stripe claims new local acquiring in Indonesia [D] [H]
A17: India | B17: =B7 -> 18000000 | C17: 0.79 | D17: 0.03 | E17: 0.05 | F17: [D] 14% soft declines (3DS friction + cross-border); UPI not supported. Local acquiring typically +5–15 pts [D]
A18: Africa | B18: =B8 -> 8900000 | C18: 0.73 | D18: 0.03 | E18: 0.05 | F18: [D] Nigerian cards declined at 29% (fraud false positives + cross-border issuer blocks)
A19: Latin America | B19: =B9 -> 11000000 | C19: 0.77 | D19: 0.03 | E19: 0.05 | F19: [D] Brazilian cards via Stripe US entity; no Pix; no OXXO
A20: Europe | B20: =B10 -> 10000000 | C20: 0.86 | D20: 0 | E20: 0 | F20: [D] Already local acquiring — no uplift modelled
A21: North America | B21: =B11 -> 7100000 | C21: 0.88 | D21: 0 | E21: 0 | F21: [D] Domestic processing — no uplift modelled
A23: C. Yuno pricing (proposal)
A24: Platform fee — per transaction | B24: 0.08 | C24: [D] Bottom of Yuno typical range ($0.08–0.15) given scale
A25: Platform fee — % of volume | B25: 0.003 | C25: [D] Bottom of Yuno typical range (0.3–0.6%)
A26: Success fee — % of loss-making-region volume | B26: 0.001 | C26: Payable only if agreed uplift per region is met (risk-sharing, not a guarantee)
A27: Loss-making-region volume (SEA, India, Africa, LatAm) | B27: =SUM(B16:B19) -> 71900000 | C27: [C]
A29: D. Operations, recovery economics and switching cost
A30: Routing-layer maintenance (0.5 FTE) | B30: 60000 | C30: [D] Eliminated with Yuno
A31: Manual failed-payment recovery labour | B31: 85000 | C31: [D]
A32: Share of manual recovery labour automated | B32: 0.7 | C32: [H] Automated retries/dunning replace most manual emails
A33: All-in processing cost on recovered revenue | B33: 0.03 | C33: [H] Recovered transactions also pay MDR + Yuno fee
A34: Risk adjustment applied to conservative uplift | B34: 0.5 | C34: [H] CFO-grade haircut: only 50% of conservative case counted for payback
A35: Switching cost — Yuno-led, phased | B35: 150000 | C35: [H] To validate with Solutions Engineering
A36: Switching cost — worst case (CFO estimate) | B36: 400000 | C36: [D] Amara: 6-month migration
A37: Current cost as reported by NexaLearn finance | B37: 3340000 | C37: [D] Bottom-up model differs: finance applies $0.30 to all 2.1M tx [C]
A39: E. Sensitivity inputs
A40: Alternative transaction count (max consistent with price ranges) | B40: 1290000 | C40: [C] 68% subs at ≥$199 ⇒ ≤304K tx; 32% courses at ≥$29 ⇒ ≤982K tx
A41: Alternative TPV (finance pacing this year) | B41: 103000000 | C41: [D]

Sheet Model
A1: Model
A3: 1. PSP fees (MDR) by segment — % component and per-transaction component
A4: Segment | B4: Current — % | C4: Current — fixed | D4: Stripe offer — % | E4: Stripe offer — fixed | F4: Stripe+Yuno cons — % | G4: Stripe+Yuno cons — fixed | H4: Stripe+Yuno base — % | I4: Stripe+Yuno base — fixed
A5: =Inputs!A5 -> SEA — Stripe cards | B5: =Inputs!$B5*Inputs!E5 -> 675700 | C5: =Inputs!$C5*Inputs!F5 -> 243000 | D5: =Inputs!$B5*Inputs!G5 -> 605800 | E5: =Inputs!$C5*Inputs!H5 -> 202500 | F5: =Inputs!$B5*Inputs!I5 -> 605800 | G5: =Inputs!$C5*Inputs!J5 -> 202500 | H5: =Inputs!$B5*Inputs!K5 -> 605800 | I5: =Inputs!$C5*Inputs!L5 -> 202500
A6: =Inputs!A6 -> SEA — Xendit APMs | B6: =Inputs!$B6*Inputs!E6 -> 342400 | C6: =Inputs!$C6*Inputs!F6 -> 27500 | D6: =Inputs!$B6*Inputs!G6 -> 342400 | E6: =Inputs!$C6*Inputs!H6 -> 27500 | F6: =Inputs!$B6*Inputs!I6 -> 342400 | G6: =Inputs!$C6*Inputs!J6 -> 27500 | H6: =Inputs!$B6*Inputs!K6 -> 342400 | I6: =Inputs!$C6*Inputs!L6 -> 27500
A7: =Inputs!A7 -> India | B7: =Inputs!$B7*Inputs!E7 -> 522000 | C7: =Inputs!$C7*Inputs!F7 -> 102000 | D7: =Inputs!$B7*Inputs!G7 -> 468000 | E7: =Inputs!$C7*Inputs!H7 -> 85000 | F7: =Inputs!$B7*Inputs!I7 -> 450000 | G7: =Inputs!$C7*Inputs!J7 -> 0 | H7: =Inputs!$B7*Inputs!K7 -> 360000 | I7: =Inputs!$C7*Inputs!L7 -> 0
A8: =Inputs!A8 -> Africa | B8: =Inputs!$B8*Inputs!E8 -> 311500 | C8: =Inputs!$C8*Inputs!F8 -> 28500 | D8: =Inputs!$B8*Inputs!G8 -> 311500 | E8: =Inputs!$C8*Inputs!H8 -> 28500 | F8: =Inputs!$B8*Inputs!I8 -> 222500 | G8: =Inputs!$C8*Inputs!J8 -> 0 | H8: =Inputs!$B8*Inputs!K8 -> 178000 | I8: =Inputs!$C8*Inputs!L8 -> 0
A9: =Inputs!A9 -> LatAm | B9: =Inputs!$B9*Inputs!E9 -> 319000 | C9: =Inputs!$C9*Inputs!F9 -> 84000 | D9: =Inputs!$B9*Inputs!G9 -> 286000 | E9: =Inputs!$C9*Inputs!H9 -> 70000 | F9: =Inputs!$B9*Inputs!I9 -> 330000 | G9: =Inputs!$C9*Inputs!J9 -> 0 | H9: =Inputs!$B9*Inputs!K9 -> 275000 | I9: =Inputs!$C9*Inputs!L9 -> 0
A10: =Inputs!A10 -> Europe | B10: =Inputs!$B10*Inputs!E10 -> 290000 | C10: =Inputs!$C10*Inputs!F10 -> 72000 | D10: =Inputs!$B10*Inputs!G10 -> 260000 | E10: =Inputs!$C10*Inputs!H10 -> 60000 | F10: =Inputs!$B10*Inputs!I10 -> 260000 | G10: =Inputs!$C10*Inputs!J10 -> 60000 | H10: =Inputs!$B10*Inputs!K10 -> 260000 | I10: =Inputs!$C10*Inputs!L10 -> 60000
A11: =Inputs!A11 -> North America | B11: =Inputs!$B11*Inputs!E11 -> 205900 | C11: =Inputs!$C11*Inputs!F11 -> 69000 | D11: =Inputs!$B11*Inputs!G11 -> 184600 | E11: =Inputs!$C11*Inputs!H11 -> 57500 | F11: =Inputs!$B11*Inputs!I11 -> 184600 | G11: =Inputs!$C11*Inputs!J11 -> 57500 | H11: =Inputs!$B11*Inputs!K11 -> 184600 | I11: =Inputs!$C11*Inputs!L11 -> 57500
A12: Total | B12: =SUM(B5:B11) -> 2666500 | C12: =SUM(C5:C11) -> 626000 | D12: =SUM(D5:D11) -> 2458300 | E12: =SUM(E5:E11) -> 531000 | F12: =SUM(F5:F11) -> 2395300 | G12: =SUM(G5:G11) -> 347500 | H12: =SUM(H5:H11) -> 2205800 | I12: =SUM(I5:I11) -> 347500
A14: 2. Total cost of ownership (annual, $)
A15: Line | B15: Current state | C15: Stripe offer (renew only) | D15: Stripe + Yuno — conservative | E15: Stripe + Yuno — base | F15: Tag
A16: PSP fees (MDR) | B16: =B12+C12 -> 3292500 | C16: =D12+E12 -> 2989300 | D16: =F12+G12 -> 2742800 | E16: =H12+I12 -> 2553300 | F16: [D][C][P][H]
A17: Yuno platform fee (per tx) | B17: 0 | C17: 0 | D17: =Inputs!$C$12*Inputs!$B$24 -> 176000 | E17: =Inputs!$C$12*Inputs!$B$24 -> 176000 | F17: [C]
A18: Yuno platform fee (% of volume) | B18: 0 | C18: 0 | D18: =Inputs!$B$12*Inputs!$B$25 -> 267000 | E18: =Inputs!$B$12*Inputs!$B$25 -> 267000 | F18: [C]
A19: Yuno success fee (if uplift met) | B19: 0 | C19: 0 | D19: =Inputs!$B$27*Inputs!$B$26 -> 71900 | E19: =Inputs!$B$27*Inputs!$B$26 -> 71900 | F19: [C]
A20: Routing-layer maintenance | B20: =Inputs!$B$30 -> 60000 | C20: =Inputs!$B$30 -> 60000 | D20: 0 | E20: 0 | F20: [D]
A21: Manual recovery labour | B21: =Inputs!$B$31 -> 85000 | C21: =Inputs!$B$31 -> 85000 | D21: =Inputs!$B$31*(1-Inputs!$B$32) -> 25500 | E21: =Inputs!$B$31*(1-Inputs!$B$32) -> 25500 | F21: [D][H]
A22: Total annual payments TCO | B22: =SUM(B16:B21) -> 3437500 | C22: =SUM(C16:C21) -> 3134300 | D22: =SUM(D16:D21) -> 3283200 | E22: =SUM(E16:E21) -> 3093700 | F22: [C]
A23: Δ vs current (negative = saving) | C23: =C22-$B$22 -> -303200 | D23: =D22-$B$22 -> -154300 | E23: =E22-$B$22 -> -343800 | F23: [C]
A24: Δ vs Stripe offer (negative = saving) | D24: =D22-$C$22 -> 148900 | E24: =E22-$C$22 -> -40600 | F24: [C]
A25: Effective PSP+Yuno rate on TPV | B25: =(B16+B17+B18+B19)/Inputs!$B$12 -> 0.036994382 | C25: =(C16+C17+C18+C19)/Inputs!$B$12 -> 0.03358764 | D25: =(D16+D17+D18+D19)/Inputs!$B$12 -> 0.036603371 | E25: =(E16+E17+E18+E19)/Inputs!$B$12 -> 0.034474157 | F25: [C]
A26: Memo: current cost reported by NexaLearn finance | B26: =Inputs!B37 -> 3340000 | F26: [D] Gap vs bottom-up = $0.30 applied to all 2.1M tx
A28: 3. Revenue recovery from approval-rate uplift (gross, annual)
A29: Region | B29: Approved volume | C29: Approval rate | D29: Attempted volume | E29: Recovered — conservative | F29: Recovered — base | G29: Recovered — risk-adjusted
A30: =Inputs!A16 -> Southeast Asia | B30: =Inputs!B16 -> 34000000 | C30: =Inputs!C16 -> 0.81 | D30: =IF(C30>0,B30/C30,0) -> 41975309 | E30: =D30*Inputs!D16 -> 629629.63 | F30: =D30*Inputs!E16 -> 1259259.3 | G30: =E30*Inputs!$B$34 -> 314814.81
A31: =Inputs!A17 -> India | B31: =Inputs!B17 -> 18000000 | C31: =Inputs!C17 -> 0.79 | D31: =IF(C31>0,B31/C31,0) -> 22784810 | E31: =D31*Inputs!D17 -> 683544.3 | F31: =D31*Inputs!E17 -> 1139240.5 | G31: =E31*Inputs!$B$34 -> 341772.15
A32: =Inputs!A18 -> Africa | B32: =Inputs!B18 -> 8900000 | C32: =Inputs!C18 -> 0.73 | D32: =IF(C32>0,B32/C32,0) -> 12191781 | E32: =D32*Inputs!D18 -> 365753.42 | F32: =D32*Inputs!E18 -> 609589.04 | G32: =E32*Inputs!$B$34 -> 182876.71
A33: =Inputs!A19 -> Latin America | B33: =Inputs!B19 -> 11000000 | C33: =Inputs!C19 -> 0.77 | D33: =IF(C33>0,B33/C33,0) -> 14285714 | E33: =D33*Inputs!D19 -> 428571.43 | F33: =D33*Inputs!E19 -> 714285.71 | G33: =E33*Inputs!$B$34 -> 214285.71
A34: =Inputs!A20 -> Europe | B34: =Inputs!B20 -> 10000000 | C34: =Inputs!C20 -> 0.86 | D34: =IF(C34>0,B34/C34,0) -> 11627907 | E34: =D34*Inputs!D20 -> 0 | F34: =D34*Inputs!E20 -> 0 | G34: =E34*Inputs!$B$34 -> 0
A35: =Inputs!A21 -> North America | B35: =Inputs!B21 -> 7100000 | C35: =Inputs!C21 -> 0.88 | D35: =IF(C35>0,B35/C35,0) -> 8068181.8 | E35: =D35*Inputs!D21 -> 0 | F35: =D35*Inputs!E21 -> 0 | G35: =E35*Inputs!$B$34 -> 0
A36: Total | B36: =SUM(B30:B35) -> 89000000 | D36: =SUM(D30:D35) -> 1.109337e+08 | E36: =SUM(E30:E35) -> 2107498.8 | F36: =SUM(F30:F35) -> 3722374.5 | G36: =SUM(G30:G35) -> 1053749.4
A38: 4. Net annual benefit of Stripe + Yuno vs Stripe offer, and payback
A39: Line | B39: Risk-adjusted | C39: Conservative | D39: Base | E39: Tag
A40: Gross revenue recovered | B40: =G36 -> 1053749.4 | C40: =E36 -> 2107498.8 | D40: =F36 -> 3722374.5 | E40: [C]
A41: Less: processing cost on recovered revenue | B41: =-B40*Inputs!$B$33 -> -31612.482 | C41: =-C40*Inputs!$B$33 -> -63224.964 | D41: =-D40*Inputs!$B$33 -> -111671.24 | E41: [H]
A42: Net revenue recovered | B42: =B40+B41 -> 1022136.9 | C42: =C40+C41 -> 2044273.8 | D42: =D40+D41 -> 3610703.3 | E42: [C]
A43: Less: extra TCO vs Stripe offer (fees + ops) | B43: =-D24 -> -148900 | C43: =-D24 -> -148900 | D43: =-E24 -> 40600 | E43: [C]
A44: Net annual benefit vs Stripe offer | B44: =B42+B43 -> 873236.91 | C44: =C42+C43 -> 1895373.8 | D44: =D42+D43 -> 3651303.3 | E44: [C]
...

Sheet Sensitivity
A1: Sensitivity
A3: Fixed per-transaction components scale with transaction count; everything scales with TPV (constant ticket).
B4: tx factor | C4: =Inputs!B40/Inputs!C12 -> 0.58636364 | D4: =Inputs!B41/Inputs!B12 -> 1.1573034
A5: Output | B5: Base model (2.2M tx, $89M) | C5: Tx = 1.29M | D5: TPV = $103M
A6: Current TCO | B6: =Model!B22 -> 3437500 | C6: =Model!B12+Model!C12*$C$4+Model!B20+Model!B21 -> 3178563.6 | D6: =(Model!B12+Model!C12)*$D$4+Model!B20+Model!B21 -> 3955421.3
A7: Stripe offer TCO | B7: =Model!C22 -> 3134300 | C7: =Model!D12+Model!E12*$C$4+Model!C20+Model!C21 -> 2914659.1 | D7: =(Model!D12+Model!E12)*$D$4+Model!C20+Model!C21 -> 3604527
A8: Stripe + Yuno TCO (conservative) | B8: =Model!D22 -> 3283200 | C8: =Model!F12+Model!G12*$C$4+Model!D17*$C$4+Model!D18+Model!D19+Model!D21 -> 3066661.4 | D8: =(Model!F12+Model!G12+Model!D17+Model!D18+Model!D19)*$D$4+Model!D21 -> 3795647.2
A9: Net annual benefit vs Stripe offer (risk-adjusted) | B9: =Model!B44 -> 873236.91 | C9: =Model!B42-(C8-C7) -> 870134.64 | D9: =Model!B42*$D$4-(D8-D7) -> 991802.27
